2022-09-19 19:15:42,084 INFO    MainThread:31320 [internal.py:wandb_internal():90] W&B internal server running at pid: 31320, started at: 2022-09-19 19:15:42.083954
2022-09-19 19:15:42,085 INFO    WriterThread:31320 [datastore.py:open_for_write():75] open: /media/sasank/LinuxStorage/Dropbox (UFL)/LitJTML/wandb/run-20220919_191541-2022-09-19-19:15:41/run-2022-09-19-19:15:41.wandb
2022-09-19 19:15:42,086 DEBUG   SenderThread:31320 [sender.py:send():236] send: header
2022-09-19 19:15:42,086 DEBUG   SenderThread:31320 [sender.py:send():236] send: run
2022-09-19 19:15:42,199 ERROR   SenderThread:31320 [internal_api.py:execute():161] 400 response executing GraphQL.
2022-09-19 19:15:42,200 ERROR   SenderThread:31320 [internal_api.py:execute():162] {"errors":[{"message":"invalid run name 2022-09-19-19:15:41, cannot contain character \":\"","path":["upsertBucket"]}],"data":{"upsertBucket":null}}
2022-09-19 19:15:43,086 INFO    HandlerThread:31320 [handler.py:finish():806] shutting down handler
2022-09-19 19:15:43,086 INFO    WriterThread:31320 [datastore.py:close():279] close: /media/sasank/LinuxStorage/Dropbox (UFL)/LitJTML/wandb/run-20220919_191541-2022-09-19-19:15:41/run-2022-09-19-19:15:41.wandb
2022-09-19 19:15:43,086 ERROR   MainThread:31320 [internal.py:wandb_internal():165] Thread SenderThread:
Traceback (most recent call last):
  File "/home/sasank/miniconda3/envs/sasank-jtml-env/lib/python3.9/site-packages/wandb/apis/normalize.py", line 25, in wrapper
    return func(*args, **kwargs)
  File "/home/sasank/miniconda3/envs/sasank-jtml-env/lib/python3.9/site-packages/wandb/sdk/internal/internal_api.py", line 1341, in upsert_run
    response = self.gql(mutation, variable_values=variable_values, **kwargs)
  File "/home/sasank/miniconda3/envs/sasank-jtml-env/lib/python3.9/site-packages/wandb/sdk/lib/retry.py", line 108, in __call__
    result = self._call_fn(*args, **kwargs)
  File "/home/sasank/miniconda3/envs/sasank-jtml-env/lib/python3.9/site-packages/wandb/sdk/internal/internal_api.py", line 158, in execute
    return self.client.execute(*args, **kwargs)
  File "/home/sasank/miniconda3/envs/sasank-jtml-env/lib/python3.9/site-packages/wandb/vendor/gql-0.2.0/wandb_gql/client.py", line 52, in execute
    result = self._get_result(document, *args, **kwargs)
  File "/home/sasank/miniconda3/envs/sasank-jtml-env/lib/python3.9/site-packages/wandb/vendor/gql-0.2.0/wandb_gql/client.py", line 60, in _get_result
    return self.transport.execute(document, *args, **kwargs)
  File "/home/sasank/miniconda3/envs/sasank-jtml-env/lib/python3.9/site-packages/wandb/vendor/gql-0.2.0/wandb_gql/transport/requests.py", line 39, in execute
    request.raise_for_status()
  File "/home/sasank/miniconda3/envs/sasank-jtml-env/lib/python3.9/site-packages/requests/models.py", line 1021, in raise_for_status
    raise HTTPError(http_error_msg, response=self)
requests.exceptions.HTTPError: 400 Client Error: Bad Request for url: https://api.wandb.ai/graphql

During handling of the above exception, another exception occurred:

Traceback (most recent call last):
  File "/home/sasank/miniconda3/envs/sasank-jtml-env/lib/python3.9/site-packages/wandb/sdk/internal/internal_util.py", line 51, in run
    self._run()
  File "/home/sasank/miniconda3/envs/sasank-jtml-env/lib/python3.9/site-packages/wandb/sdk/internal/internal_util.py", line 102, in _run
    self._process(record)
  File "/home/sasank/miniconda3/envs/sasank-jtml-env/lib/python3.9/site-packages/wandb/sdk/internal/internal.py", line 310, in _process
    self._sm.send(record)
  File "/home/sasank/miniconda3/envs/sasank-jtml-env/lib/python3.9/site-packages/wandb/sdk/internal/sender.py", line 238, in send
    send_handler(record)
  File "/home/sasank/miniconda3/envs/sasank-jtml-env/lib/python3.9/site-packages/wandb/sdk/internal/sender.py", line 696, in send_run
    self._init_run(run, config_value_dict)
  File "/home/sasank/miniconda3/envs/sasank-jtml-env/lib/python3.9/site-packages/wandb/sdk/internal/sender.py", line 720, in _init_run
    server_run, inserted = self._api.upsert_run(
  File "/home/sasank/miniconda3/envs/sasank-jtml-env/lib/python3.9/site-packages/wandb/apis/normalize.py", line 27, in wrapper
    raise CommError(err.response, err)
wandb.errors.CommError: <Response [400]>
2022-09-19 19:15:45,101 INFO    MainThread:31320 [internal.py:handle_exit():80] Internal process exited
